Workbook

Sheet 📋 Instrucciones
B1: 📊 PORTAFOLIO OTIC — SISTEMA DE DASHBOARD
B2: Guía de uso del sistema
B5: FLUJO DE TRABAJO
B6: Paso 1 — Actualizar Data Original | C6: Vaya a la hoja "Data Original" y actualice fechas, estados y equipos de los proyectos.
B7: Paso 2 — Cargar tareas por proyecto | C7: Vaya a la hoja del proyecto (P1, P2... P29) y llene las tareas comprometidas con fecha inicio, fin y % avance.
B8: Paso 3 — Exportar JSON | C8: Vaya a la hoja "🚀 Exportar" y presione el botón EXPORTAR DASHBOARD. Se generará el archivo datos_otic.json.
B9: Paso 4 — Abrir Dashboard | C9: Abra el archivo dashboard_otic.html en Chrome o Edge. Cargue el archivo datos_otic.json cuando se solicite.
B11: SEMÁFOROS DE FECHAS
B12: 🔴 Crítico | C12: Menos de 5 días para la fecha clave
B13: 🟡 Alerta | C13: Entre 5 y 20 días para la fecha clave
B14: 🟢 En Tiempo | C14: Más de 20 días para la fecha clave
B15: ✅ Completada | C15: Tarea con 100% de avance
B17: CAMPOS AMARILLOS | C17: Son los campos que usted debe llenar / actualizar
B18: CAMPOS GRISES | C18: Se calculan automáticamente — NO modificar

Sheet Data Original
A1: No. | B1: ESTADO | C1: PROYECTO | D1: COMPROBACION LINEA PAA (27/01/2026) | E1: MODALIDAD | F1: OBJETO | G1: PLAZO (MESES) | H1: MULTIPROCESO | I1: VALOR INICIAL PROGRAMADO | J1: INCREMENTOS | K1: DISMINUCIONES | L1: APROPIACION VIGENTE ACTUAL BOGDATA | M1: APROPIACIÓN VIGENTE ACTUAL BOGDATA (PAA 27/01/2026) | N1: % INCIDENCIA | O1: FECHA ENTREGA ABOGADO OTIC | P1: DIAS RESTANTES ENTREGA ABOGADO OTIC | Q1: FECHA SOLICITUD MESA DE TRABAJO (27/01/2026) | R1: FECHA MESA DE TRABAJO | S1: DIAS RESTANTES SOLICITUD MESA DE TRABAJO | T1: FECHA RADICACION CONTRATACION (27/01/2026) | U1: FECHA RADICACION CONTRATACION | V1: DIAS RESTANTES RADICACION CONTRATACION | W1: FECHA APROX ADJUDICACION (27/01/2026) | X1: FECHA APROX ADJUDICACION | Y1: ESTRUCTURADOR OTIC | Z1: ABOGADO OTIC | AA1: EVALUADORES OTIC | AB1: SUPERVISOR OTIC | AC1: APOYO SUPERVISION OTIC
A2: P1 | B2: En Progreso | C2: DARUMA | D2: SGC-244 | E2: 12.4-CONTRATACIÓN DIRECTA-CONVENIOS O CONTRATOS INTERADMINISTRATIVOS | F2: ACTUALIZACION DEL SOFTWARE PARA LA ADMINISTRACION DE LA INFORMACION DEL MODELO INTEGRADO DE PLANEACION Y GESTION MIPG PARA LA SECRETARIA DISTRITAL DE MOVILIDAD | G2: 7 | H2: 25. DARUMA - ORDENADOR DEL GASTO CORPORATIVA | I2: 15000000 | J2: 0 | K2: 0 | L2: 15000000 | M2: 15000000 | N2: 0.033422433 | O2: 46162 | P2: 65 | Q2: 46260 | R2: 46175 | S2: 74 | T2: 46195 | U2: 46195 | V2: 88 | W2: 46243 | X2: 46280 | Y2: Mayerly Benavides | Z2: Carlos Gonzales | AA2: N.A. | AB2: Mayerly Benavides | AC2: Jhon Edison Rozo
A3: P2 | B3: En Progreso | C3: ETAPA 2 SOLUCIONES PLATAFORMA TECNOLOGICA | D3: SGC-248 | E3: 200-LICITACIÓN PÚBLICA | F3: ETAPA 2 ADQUIRIR IMPLEMENTAR ACTUALIZAR Y SOPORTAR SOLUCIONES DE TECNOLOGIA Y SERVICIOS PARA CONTINUAR EL PROCESO DE RENOVACION DE LA PLATAFORMA TECNOLOGICA DE LA SECRETARIA DISTRITAL DE MOVILIDAD | G3: 6 | H3: PROCESO ÚNICO: ADQUISICIÓN EQUIPOS | I3: 2175194438 | J3: 0 | K3: 0 | L3: 2175194438 | M3: 2175194438 | N3: 0.16623245 | O3: 46191 | P3: 86 | Q3: 46126 | R3: 46204 | S3: 95 | T3: 46224 | U3: 46224 | V3: 109 | W3: 46357 | X3: 46146 | Y3: Yecid Rodriguez Martha Zambrano | Z3: Gabriela Delgado | AA3: Miguel Alvarez Oscar Correa
A4: P3 | B4: En Progreso | C4: GARANTIA EXTENDIDA LOTE 3 | D4: SGC-357 | E4: 13.1-PROCESO MÍNIMA CUANTÍA | F4: RENOVACION DE SOPORTE DE FABRICA Y GARANTIA EXTENDIDA PARA LA PLATAFORMA LENOVO DE LA SECRETARIA DISTRITAL DE MOVILIDAD | G4: 2 | H4: 25. DARUMA - ORDENADOR DEL GASTO CORPORATIVA | I4: 120000000 | J4: 0 | K4: 420648972 | L4: 120000000 | M4: 120000000 | N4: 0.05850546 | O4: 46049 | P4: -18 | Q4: 46134 | R4: 46060 | S4: -9 | T4: 46080 | U4: 46080 | V4: 7 | W4: 46136 | X4: 46154 | Y4: Miguel Barrera | Z4: Gabriela Delgado | AA4: Mayerly Benavidez | AB4: Miguel Barrera
A5: P4 | B5: En Progreso | C5: EQUIPOS ACTIVOS DE RED ETAPA 3 | D5: SGC-359 | E5: 7-SELECCIÓN ABREVIADA - SUBASTA INVERSA | F5: ETAPA 3 ADQUISICION DE EQUIPOS ACTIVOS DE RED PARA LA SECRETARIA DISTRITAL DE MOVILIDAD | G5: 4 | H5: 07. EQUIPOS ACTIVOS DE RED ETAPA 3 - ORDENADOR DEL GASTO: CORPORATIVA | I5: 479157000 | J5: 0 | K5: 0 | L5: 479157000 | M5: 479157000 | N5: 0.00022850942 | O5: 46247 | P5: 126 | Q5: 46224 | R5: 46260 | S5: 135 | T5: 46280 | U5: 46280 | V5: 149 | W5: 46378 | X5: 46244 | Y5: Javier Pineda Oscar Bolaños | Z5: Gabriela Delgado | AA5: Marisol Caro Oscar Correa Yecid Rodriguez | AB5: Javier Pineda | AC5: Oscar Bolaños
A6: P5 | B6: En Progreso | C6: GOOGLE WORKSPACE | D6: SGC-361 | E6: 14.2-SELECCIÓN ABREVIADA - COMPRA CATALOGO ACUERDO MARCO PRECIOS | F6: LICENCIAMIENTO DE LOS SERVICIOS DE GOOGLE WORKSPACE Y EL SOPORTE TECNICO PARA LA SECRETARIA DISTRITAL DE MOVILIDAD | G6: 12 | H6: 09. SOFTWARE-LICENCIAMIENTO GOOGLE WORKSPACE - ORDENADOR DEL GASTO CORPORATIVA | I6: 2383173000 | J6: 1392613000 | K6: 0 | L6: 2383173000 | M6: 2383173000 | N6: 0.097138338 | O6: 46113 | P6: 30 | Q6: 46018 | R6: 46126 | S6: 39 | T6: 46146 | U6: 46146 | V6: 53 | W6: 46216 | X6: 46038 | Y6: Jonathan Pernet | Z6: Gabriela Delgado | AA6: N.A. | AB6: Javier Pineda | AC6: Jonathan Pernet
A7: P6 | B7: En Progreso | C7: NUBE | D7: SGC-362 | E7: 14.2-SELECCIÓN ABREVIADA - COMPRA CATALOGO ACUERDO MARCO PRECIOS | F7: PRESTAR SERVICIO DE NUBE PARA LA SECRETARIA DISTRITAL DE MOVILIDAD | G7: 6 | H7: 51. NUBE - ORDENADOR DEL GASTO: CORPORATIVA | I7: 838757028 | K7: 0 | L7: 838757028 | M7: 838757028 | N7: 0.056120827 | O7: 46217 | P7: 104 | Q7: 46219 | R7: 46228 | S7: 112 | T7: 46248 | U7: 46248 | V7: 127 | W7: 46318 | X7: 46239 | Y7: Jonathan Pernet | Z7: Gabriela Delgado | AA7: N.A. | AB7: Adriana Villamizar | AC7: Jonathan Pernet
A8: P7 | B8: En Progreso | C8: IMPRESIÓN ETIQUETAS | D8: SGC-365 | E8: 13.2-PROCESO MINIMA CUANTIA - ADQUISICION GRANDES SUPERFICIES | F8: REALIZAR LA RENOVACION DEL SOPORTE DE LA LICENCIA DEL SOFTWARE DE IMPRESION DE ETIQUETAS PARA LA SECRETARIA DISTRITAL DE MOVILIDAD | G8: 2 | H8: PROCESO ÚNICO: RENOVACIÓN IMPRESIÓN ETIQUETAS | I8: 3276000 | J8: 247000000 | K8: 0 | L8: 3276000 | M8: 3276000 | N8: 0.038399628 | O8: 46211 | P8: 100 | Q8: 46218 | R8: 46224 | S8: 109 | T8: 46244 | U8: 46244 | V8: 123 | W8: 46303 | X8: 46238 | Y8: Miguel Barrera | Z8: Gabriela Delgado | AA8: N.A. | AB8: Miguel Barrera | AC8: N.A.
A9: P8 | B9: En Progreso | C9: ARQUITECTURA EMPRESARIAL | D9: SGC-366 | E9: 200-LICITACIÓN PÚBLICA | F9: PRESTAR LOS SERVICIOS PARA INCORPORAR DESARROLLAR E IMPLEMENTAR LA ARQUITECTURA EMPRESARIAL SIGUIENDO EL MODELO DE REFERENCIA DEL MINISTERIO DE TECNOLOGIAS DE LA INFORMACION Y LAS COMUNICACIONES Y APLICAR LA ESTRATEGIA DE GOBIERNO Y OPERACION EN LA SECRETARIA DISTRITAL DE MOVILIDAD | G9: 9 | H9: PROCESO ÚNICO - ARQUITECTURA EMPRESARIAL | I9: 2204000000 | J9: 5557000 | K9: 0 | L9: 2204000000 | M9: 2204000000 | N9: 0.014417857 | O9: 46035 | P9: -28 | Q9: 46154 | R9: 46046 | S9: -19 | T9: 46066 | U9: 46066 | V9: -5 | W9: 46199 | X9: 46174 | Y9: Adriana Villamizar Jorge Neira | Z9: Gabriela Delgado | AA9: Ernesto Guevara Jose Rene Gonzales Jorge Luis Vargas Yecid Rodriguez | AB9: Adriana Villamizar | AC9: Jorge Neira
A10: P9 | B10: En Progreso | C10: LICENCIAS MICROSOFT | D10: SGC-367 | E10: 14.2-SELECCIÓN ABREVIADA - COMPRA CATALOGO ACUERDO MARCO PRECIOS | F10: ADQUISICION Y RENOVACION DE LICENCIAS DE PRODUCTOS MICROSOFT PARA LA SECRETARIA DISTRITAL DE MOVILIDAD | G10: 3 | H10: PROCESO ÚNICO: LICENCIAS MICROSOFT | I10: 350000000 | J10: 0 | K10: 9886481 | L10: 350000000 | M10: 350000000 | N10: 0.0092714085 | O10: 46057 | P10: -12 | Q10: 46154 | R10: 46070 | S10: -3 | T10: 46090 | U10: 46090 | V10: 13 | W10: 46160 | X10: 46174 | Y10: Javier Pineda | Z10: Gabriela Delgado | AA10: N.A. | AB10: Javier Pineda | AC10: Jonathan Pernet
A11: P10 | B11: En Progreso | C11: ANTIVIRUS Y XDR | D11: SGC-368 | E11: 7-SELECCIÓN ABREVIADA - SUBASTA INVERSA | F11: RENOVACIÓN DE LA SUSCRIPCION DEL LICENCIAMIENTO DE HERRAMIENTA ANTIVIRUS Y XDR PARA LA SECRETARIA DISTRITAL DE MOVILIDAD | G11: 2 | H11: PROCESO ÚNICO: ANTIVIRUS | I11: 550512000 | J11: 0 | K11: 0 | L11: 550512000 | M11: 550512000 | N11: 0.083952172 | O11: 46155 | P11: 60 | Q11: 46128 | R11: 46168 | S11: 69 | T11: 46188 | U11: 46188 | V11: 83 | W11: 46286 | X11: 46148 | Y11: Jasvleydi Fajado Elsa Baracaldo | Z11: Gabriela Delgado | AA11: Jhon Fuentes Yecid Rodriguez | AB11: Jasvleydi Fajardo | AC11: Liliana Garzon
A12: P11 | B12: En Progreso | C12: TRANSCAD TRANSMODELER | D12: SGC-370 | E12: 12.7-CONTRATACIÓN DIRECTA-NO EXISTENCIA PLURALIDAD DE OFERENTES | F12: ADQUIRIR LA RENOVACION DEL SOPORTE Y MANTENIMIENTO DEL LICENCIAMIENTO DE TRANSCAD TRANSMODELER DE PROPIEDAD DE LA SECRETARIA DISTRITAL DE MOVILIDAD | G12: 3 | H12: PROCESO ÚNICO: TRANSCAD | I12: 206700000 | J12: 0 | K12: 0 | L12: 206700000 | M12: 206700000 | N12: 0.14734882 | O12: 46141 | P12: 50 | Q12: 46175 | R12: 46154 | S12: 59 | T12: 46174 | U12: 46174 | V12: 73 | W12: 46223 | X12: 46195 | Y12: Jorge Neira | Z12: Carlos Gonzales | AA12: N.A. | AB12: Oscar Vargas | AC12: N.A.
A13: P12 | B13: En Progreso | C13: EMME DYBAMEQ | D13: SGC-371 | E13: 12.7-CONTRATACIÓN DIRECTA-NO EXISTENCIA PLURALIDAD DE OFERENTES | F13: ADQUIRIR LA RENOVACION DEL SOPORTE Y MANTENIMIENTO DEL LICENCIAMIENTO DE EMME DYNAMEQ DE PROPIEDAD DE LA SECRETARIA DISTRITAL DE MOVILIDAD | G13: 3 | H13: PROCESO ÚNICO: EMME DYNAMEQ | I13: 132918519 | J13: 0 | K13: 0 | L13: 132918519 | M13: 132918519 | N13: 0.0024260642 | O13: 46141 | P13: 50 | Q13: 46217 | R13: 46154 | S13: 59 | T13: 46174 | U13: 46174 | V13: 73 | W13: 46223 | X13: 46237 | Y13: Jorge Neira | Z13: Carlos Gonzales | AA13: N.A. | AB13: Oscar Vargas | AC13: N.A.
A14: P13 | B14: En Progreso | C14: LICENCIAMIENTO ORACLE | D14: SGC-372 | E14: 12.7-CONTRATACIÓN DIRECTA-NO EXISTENCIA PLURALIDAD DE OFERENTES | F14: ADQUIRIR LA RENOVACION DEL SOPORTE DEL LICENCIAMIENTO ORACLE DE PROPIEDAD DE LA SECRETARIA DISTRITAL DE MOVILIDAD | G14: 3 | H14: PROCESO ÚNICO: SOFTWARE-LICENCIAMIENTO ORACLE | I14: 1203571000 | J14: 111039000 | K14: 0 | L14: 1203571000 | M14: 1203571000 | N14: 0.0083703086 | O14: 46115 | P14: 32 | Q14: 46305 | R14: 46128 | S14: 41 | T14: 46148 | U14: 46148 | V14: 55 | W14: 46197 | X14: 46325 | Y14: Miguel Barrera | Z14: Gabriela Delgado | AB14: Miguel Barrera
A15: P14 | B15: En Progreso | C15: ARCGIS | D15: SGC-373 | E15: 14.2-SELECCIÓN ABREVIADA - COMPRA CATALOGO ACUERDO MARCO PRECIOS | F15: RENOVACION DEL SOFTWARE ESPECIALIZADO PARA SISTEMAS DE INFORMACION GEOGRAFICA ARCGIS BAJO LA MODALIDAD DE ACUERDO DE LICENCIAMIENTO CORPORATIVO ELA | G15: 3 | H15: PROCESO ÚNICO: SOFTWARE-RENOVACIÓN ARCGIS | I15: 2112450000 | J15: 0 | K15: 0 | L15: 2112450000 | M15: 2112450000 | N15: 0.00071949778 | O15: 46162 | P15: 65 | Q15: 46127 | R15: 46175 | S15: 74 | T15: 46195 | U15: 46195 | V15: 88 | W15: 46265 | X15: 46147 | Y15: Dora Estrada | Z15: Gabriela Delgado | AA15: N.A. | AB15: Dora Estrada | AC15: Ernesto Guevara
A16: P15 | B16: En Progreso | C16: LICENCIAMIENTO ORACLE LINUX | D16: SGC-374 | E16: 13.1-PROCESO MÍNIMA CUANTÍA | F16: SUSCRIPCION DEL SERVICIO DE SOPORTE Y MANTENIMIENTO DEL LICENCIAMIENTO ORACLE LINUX VIRTUALIZATION MANAGER DE PROPIEDAD DE LA SDM | G16: 12 | H16: PROCESO ÚNICO: ORACLE LINUX | I16: 34781000 | J16: 0 | K16: 0 | L16: 34781000 | M16: 34781000 | N16: 0.0080961112 | O16: 46204 | P16: 95 | Q16: 46158 | R16: 46217 | S16: 104 | T16: 46237 | U16: 46237 | V16: 118 | W16: 46293 | X16: 46178 | Y16: Miguel Barrera | Z16: Carlos Gonzales | AA16: Oscar Correa | AB16: Miguel Barrera
A17: P16 | B17: En Progreso | C17: LICENCIACION ADOBE ACROBAT | D17: SGC-375 | E17: 13.2-PROCESO MINIMA CUANTIA - ADQUISICION GRANDES SUPERFICIES | F17: RENOVACION DEL LICENCIAMIENTO POR SUSCRIPCION DE ADOBE ACROBAT PRO ADOBE CREATIVE CLOUD Y MICROSOFT POWER BI PARA LA SECRETARIA DISTRITAL DE MOVILIDAD | G17: 3 | H17: PROCESO ÚNICO: SOFTWARE AUDIOVISUALES | I17: 120000000 | J17: 0 | K17: 0 | L17: 120000000 | M17: 120000000 | N17: 0.035730336 | O17: 46294 | P17: 159 | Q17: 46137 | R17: 46305 | S17: 167 | T17: 46325 | U17: 46325 | V17: 182 | W17: 46384 | X17: 46157 | Y17: Mayerly Benavides | Z17: Gabriela Delgado | AB17: Mayerly Benavides
A18: P17 | B18: En Progreso | C18: LENOVO XCLARITY PRO | D18: SGC-377 | E18: 13.1-PROCESO MÍNIMA CUANTÍA | F18: SUSCRIPCION Y SOPORTE DE FABRICA DEL SOFTWARE LENOVO XCLARITY PRO PARA LA SECRETARIA DISTRITAL DE MOVILIDAD | G18: 3 | H18: PROCESO ÚNICO: LENOVO XCLARITY | I18: 10315000 | J18: 57052972 | K18: 0 | L18: 10315000 | M18: 10315000 | N18: 0.065201772 | O18: 46114 | P18: 31 | Q18: 46238 | R18: 46127 | S18: 40 | T18: 46147 | U18: 46147 | V18: 54 | W18: 46203 | X18: 46258 | Y18: Yecid Rodriguez | Z18: Carlos Gonzales | AA18: Jose Rene Gonzales | AB18: Edgar Romero
A19: P18 | B19: En Progreso | C19: NAGIOS | D19: SGC-378 | E19: 13.1-PROCESO MÍNIMA CUANTÍA | F19: RENOVACION SOPORTE Y ACTUALIZACION DEL SOFTWARE NAGIOS XI Y NAGIOS NETWORK ANALYZER LA SECRETARIA DISTRITAL DE MOVILIDAD | G19: 4 | H19: PROCESO ÚNICO: NAGIOS | I19: 116069000 | J19: 0 | K19: 0 | L19: 116069000 | M19: 116069000 | N19: 0.0052729456 | O19: 46147 | P19: 54 | Q19: 46141 | R19: 46158 | S19: 62 | T19: 46178 | U19: 46178 | V19: 77 | W19: 46234 | X19: 46161 | Y19: Miguel Alvarez | Z19: Carlos Gonzales | AA19: N.A. | AB19: Miguel Barrera | AC19: N.A.
A20: P19 | B20: En Progreso | C20: PALO ALTO | D20: SGC-379 | E20: 7-SELECCIÓN ABREVIADA - SUBASTA INVERSA | F20: RENOVAR SOPORTE Y GARANTIA DE FABRICA DE LA INFRAESTRUCTURA DE SEGURIDAD DE LA INFORMACION PALOALTO PARA LA SECRETARIA DISTRITAL DE MOVILIDAD | G20: 12 | H20: PROCESO ÚNICO: PALOALTO | I20: 512244000 | J20: 0 | K20: 0 | L20: 512244000 | M20: 512244000 | N20: 0.0089234465 | O20: 46094 | P20: 17 | Q20: 46273 | R20: 46107 | S20: 26 | T20: 46127 | U20: 46127 | V20: 40 | W20: 46225 | X20: 46293 | Y20: Jasvleydi Fajardo Elsa Baracaldo | Z20: Gabriela Delgado | AA20: Jhon Fuentes | AB20: Jasvleydi Fajardo | AC20: Elsa Baracaldo
A21: P20 | B21: En Progreso | C21: NETBACKUP VERITAS | D21: SGC-380 | E21: 304-SELECCIÓN ABREVIADA-MENOR CUANTÍA | F21: RENOVAR LA SUSCRIPCION DEL LICENCIAMIENTO Y EL SOPORTE DE FABRICA DEL SOFTWARE NETBACKUP Y RENOVAR EL APPLIANCE PARA LA SOLUCION VERITAS COHESITY DE PROPIEDAD DE LA SECRETARIA DISTRITAL DE MOVILIDAD | G21: 3 | H21: PROCESO ÚNICO: NETBACKUP ENTERPRISE | I21: 934757972 | J21: 0 | K21: 0 | L21: 934757972 | M21: 934757972 | N21: 0.0022218984 | O21: 46049 | P21: -18 | Q21: 46270 | R21: 46060 | S21: -9 | T21: 46080 | U21: 46080 | V21: 7 | W21: 46171 | X21: 46290 | Y21: Oscar Correa | Z21: Gabriela Delgado | AA21: Jhon Fuentes Oscar Bolaños | AB21: Miguel Barrera
A22: P21 | B22: En Progreso | C22: LICENCIAMIENTO AUTODESK | D22: SGC-382 | E22: 7-SELECCIÓN ABREVIADA - SUBASTA INVERSA | F22: SUSCRIPCION Y RENOVACION LICENCIAS DE AUTODESK | G22: 3 | H22: 43. AUTODESK - ORDENADOR DE GASTO: CORPORATIVA | I22: 75595000 | J22: 0 | K22: 0 | L22: 75595000 | M22: 75595000 | N22: 0.0431548 | O22: 46113 | P22: 30 | Q22: 46204 | R22: 46126 | S22: 39 | T22: 46146 | U22: 46146 | V22: 53 | W22: 46244 | X22: 46224 | Y22: Dora Estrada | Z22: Carlos Gonzales | AA22: Ernesto Guevara | AB22: Dora Estrada | AC22: N.A.
A23: P22 | B23: En Progreso | C23: AUDITORIA CONTINUIIDAD DEL NEGOCIO | D23: SGC-383 | E23: 13.1-PROCESO MÍNIMA CUANTÍA | F23: PRESTAR LOS SERVICIOS PARA REALIZAR LA AUDITORIA DE RECERTIFICACION DE LA CERTIFICACION DEL SISTEMA DE GESTION DE CONTINUIDAD DEL NEGOCIO BAJO LA NORMA ISO 223012019 | G23: 2 | H23: PROCESO ÚNICO: RECERTIFICACIÓN SGCN | I23: 127930000 | J23: 0 | K23: 0 | L23: 127930000 | M23: 127930000 | N23: 0.018586828 | O23: 46260 | P23: 135 | Q23: 46074 | R23: 46273 | S23: 144 | T23: 46293 | U23: 46293 | V23: 158 | W23: 46349 | X23: 46094 | Y23: Adriana Villamizar Sandra Velasquez | Z23: Gabriela Delgado | AB23: Adriana Villamizar | AC23: Roger Alfonso
A24: P23 | B24: En Progreso | C24: AUDITORIA SEGURIDAD DE LA INFORMACION | D24: SGC-384 | E24: 13.1-PROCESO MÍNIMA CUANTÍA | F24: PRESTAR LOS SERVICIOS PARA REALIZAR LA AUDITORIA DE RECERTIFICACION DEL SISTEMA DE GESTION DE SEGURIDAD DE LA INFORMACION SGSI BAJO LA NORMA ISO/IEC 270012022 | G24: 2 | H24: PROCESO ÚNICO: RECERTIFICACIÓN SGSI | I24: 31854000 | J24: 0 | K24: 0 | L24: 31854000 | M24: 31854000 | N24: 0.051084342 | O24: 46206 | P24: 97 | Q24: 46172 | R24: 46219 | S24: 106 | T24: 46239 | U24: 46239 | V24: 120 | W24: 46295 | X24: 46192 | Y24: Jasvleydi Fajardo Jorge Vargas | Z24: Carlos Gonzales | AB24: Jasvleydi Fajardo | AC24: Elsa Baracaldo
A25: P24 | B25: RADICADO A DC | C25: ETAPA 2 SOLUCIONES PLATAFORMA TECNOLOGICA | D25: SGC-385 | E25: 200-LICITACIÓN PÚBLICA | F25: ETAPA 2 ADQUIRIR IMPLEMENTAR ACTUALIZAR Y SOPORTAR SOLUCIONES DE TECNOLOGIA Y SERVICIOS PARA CONTINUAR EL PROCESO DE RENOVACION DE LA PLATAFORMA TECNOLOGICA DE LA SECRETARIA DISTRITAL DE MOVILIDAD | G25: 6 | H25: PROCESO ÚNICO: ADQUISICIÓN EQUIPOS | I25: 263591008 | J25: 0 | K25: 0 | L25: 263591008 | M25: 263591008 | N25: 0.0034496832 | O25: 46191 | P25: 86 | Q25: 46017 | R25: 46204 | S25: 95 | T25: 46224 | U25: 46224 | V25: 109 | W25: 46357 | X25: 46037 | Y25: Yecid Rodriguez Martha Zambrano | Z25: Gabriela Delgado | AA25: Miguel Alvarez Oscar Correa
A26: P25 | B26: En Progreso | C26: (DEJAR EN CEROS) | D26: SGC-386 | E26: 14.2-SELECCIÓN ABREVIADA - COMPRA CATALOGO ACUERDO MARCO PRECIOS | F26: ADQUIRIR LA RENOVACION DE LA SUSCRIPCION DE SOPORTE INFORMIX PARA LA SECRETARIA DISTRITAL DE MOVILIDAD | G26: 2 | H26: PROCESO ÚNICO: INFORMIX | I26: 266468000 | J26: 9886481 | K26: 0 | L26: 266468000 | M26: 266468000 | N26: 0.027095211 | O26: 46063 | P26: -8 | Q26: 46145 | R26: 46074 | S26: 2 | T26: 46094 | U26: 46094 | V26: 17 | W26: 46164 | X26: 46165 | Y26: Jorge Neira | Z26: Carlos Gonzales | AA26: N.A. | AB26: Miguel Barrera | AC26: N.A.
A27: P26 | B27: En Progreso | C27: WAF | D27: SGC-387 | E27: 7-SELECCIÓN ABREVIADA - SUBASTA INVERSA | F27: PRESTAR EL SERVICIO DE WAF EN NUBE Y SOPORTE TECNICO PARA PROTECCION DE LAS APLICACIONES WEB DE LA SECRETARIA DISTRITAL DE MOVILIDAD | G27: 12 | H27: PROCESO ÚNICO: SERVICIO WAF | I27: 732365000 | J27: 0 | K27: 0 | L27: 732365000 | M27: 732365000 | N27: 0.010792467 | O27: 46142 | P27: 51 | Q27: 46137 | R27: 46155 | S27: 60 | T27: 46175 | U27: 46175 | V27: 74 | W27: 46273 | X27: 46157 | Y27: Jasvleydi Fajardo Elsa Baracaldo | Z27: Gabriela Delgado | AA27: Ernesto Guevara Marisol Caro Jose Rene Gonzales | AB27: Jasvleydi Fajardo
A28: P27 | B28: En Progreso | C28: AUDITORIAS INTERNAS | D28: SGC-390 | E28: 13.1-PROCESO MÍNIMA CUANTÍA | F28: REALIZAR LAS AUDITORIAS INTERNAS DE LOS DIFERENTES SISTEMAS DE GESTION Y DEL PLAN ESTRATEGICO DE SEGURIDAD VIAL DE LA SECRETARIA DISTRITAL DE MOVILIDAD | G28: 9 | H28: 47. AUDITORÍAS INTERNAS - ORDENADOR DEL GASTO: CORPORATIVA | I28: 49456000 | J28: 0 | K28: 0 | L28: 49456000 | M28: 49456000 | N28: 0.0027901029 | O28: 46006 | P28: -49 | Q28: 46227 | R28: 46017 | S28: -40 | T28: 46037 | U28: 46037 | V28: -26 | W28: 46093 | X28: 46247 | Y28: Adriana Villamizar | Z28: N.A. | AA28: N.A. | AB28: Jasvleydi Fajardo | AC28: N.A.
A29: P28 | B29: En Progreso | C29: SOPORTE PREMIER | D29: SGC-391 | E29: 12.7-CONTRATACIÓN DIRECTA-NO EXISTENCIA PLURALIDAD DE OFERENTES | F29: CONTRATAR LOS SERVICIOS DE SOPORTE PREMIER BAJO EL MODELO UNIFIED DE MICROSOFT PARA LA SECRETARIA DISTRITAL DE MOVILIDAD | G29: 12 | H29: PROCESO ÚNICO: SOPORTE PREMIER | I29: 388447481 | J29: 0 | K29: 0 | L29: 388447481 | M29: 388447481 | N29: 0.0010462886 | O29: 46133 | P29: 44 | Q29: 46175 | R29: 46145 | S29: 52 | T29: 46165 | U29: 46165 | V29: 67 | W29: 46214 | X29: 46195 | Y29: Jonathan Pernet | Z29: Carlos Gonzales | AA29: N.A. | AB29: Oscar Vargas | AC29: N.A.
L30: 100000000 | M30: 100000000
L31: 0 | M31: 0
L32: 0 | M32: 0
L33: 16538582446 | M33: 16538582446
L35: 16538582446

Sheet 🚀 Exportar
B1: 🚀 EXPORTAR DASHBOARD — Generar datos_otic.json
B2: Presione el botón de abajo o ejecute la macro "ExportarDashboard" para generar el archivo JSON
B4: ▶ EXPORTAR DASHBOARD (Ejecutar Macro: ExportarDashboard)
B8: INSTRUCCIONES PARA AGREGAR EL BOTÓN:
B9: 1. | C9: Guarde este archivo como .xlsm (Excel habilitado para macros)
B10: 2. | C10: Presione Alt+F11 para abrir el Editor VBA
B11: 3. | C11: En el panel izquierdo, haga clic derecho en VBAProject → Insertar → Módulo
B12: 4. | C12: Copie y pegue el código VBA que aparece más abajo en el módulo
B13: 5. | C13: Cierre el editor VBA (Alt+F4 o simplemente cierre la ventana)
B14: 6. | C14: Ahora puede ejecutar la macro desde Desarrollador → Macros → ExportarDashboard
B16: NOTA: | C16: El archivo JSON se guardará en la misma carpeta donde está el Excel
B18: CÓDIGO VBA — Copie todo el texto de abajo al Módulo VBA:
B21: '============================================================
B22: ' PORTAFOLIO OTIC — Macro de Exportación a JSON
B23: ' Instrucciones:
B24: ' 1. Guarde el archivo como .xlsm (macro habilitado)
B25: ' 2. Presione Alt+F11 → Insertar → Módulo
B26: ' 3. Pegue TODO este código en el módulo
B27: ' 4. Cierre el editor y ejecute desde Desarrollador → Macros
B28: '============================================================
B30: Sub ExportarDashboard()
B31: Dim ws As Worksheet
B32: Dim wsData As Worksheet
... B240: End Function

Sheet Formulario Tareas
B2: 📝 FORMULARIO DE INGRESO DE TAREAS
B3: Complete los campos en amarillo. Los campos en gris se calculan automáticamente.
B5: PROYECTO (ID): | E5: P1
B6: ℹ️ Ingrese el ID del proyecto (P1, P2, P3…) al que pertenecen estas tareas
B9: # | C9: NOMBRE DE LA TAREA | D9: FECHA INICIO | E9: FECHA FIN COMPROMETIDA | F9: DÍAS RESTANTES | G9: % AVANCE | H9: ESTADO
B10: 1 | F10: =IF(E10="","",E10-TODAY()) | H10: =IF(C10="","",IF(G10=1,"✅ Completada",IF(F10="","—",IF(F10>5,"🟢 En tiempo",IF(F10>=1,"🟡 Por vencer","🔴 Vencida")))))
B11: 2 | F11: =IF(E11="","",E11-TODAY()) | H11: =IF(C11="","",IF(G11=1,"✅ Completada",IF(F11="","—",IF(F11>5,"🟢 En tiempo",IF(F11>=1,"🟡 Por vencer","🔴 Vencida")))))
B12: 3 | F12: =IF(E12="","",E12-TODAY()) | H12: =IF(C12="","",IF(G12=1,"✅ Completada",IF(F12="","—",IF(F12>5,"🟢 En tiempo",IF(F12>=1,"🟡 Por vencer","🔴 Vencida")))))
B13: 4 | F13: =IF(E13="","",E13-TODAY()) | H13: =IF(C13="","",IF(G13=1,"✅ Completada",IF(F13="","—",IF(F13>5,"🟢 En tiempo",IF(F13>=1,"🟡 Por vencer","🔴 Vencida")))))
B14: 5 | F14: =IF(E14="","",E14-TODAY()) | H14: =IF(C14="","",IF(G14=1,"✅ Completada",IF(F14="","—",IF(F14>5,"🟢 En tiempo",IF(F14>=1,"🟡 Por vencer","🔴 Vencida")))))
B15: 6 | F15: =IF(E15="","",E15-TODAY()) | H15: =IF(C15="","",IF(G15=1,"✅ Completada",IF(F15="","—",IF(F15>5,"🟢 En tiempo",IF(F15>=1,"🟡 Por vencer","🔴 Vencida")))))
B16: 7 | F16: =IF(E16="","",E16-TODAY()) | H16: =IF(C16="","",IF(G16=1,"✅ Completada",IF(F16="","—",IF(F16>5,"🟢 En tiempo",IF(F16>=1,"🟡 Por vencer","🔴 Vencida")))))
B17: 8 | F17: =IF(E17="","",E17-TODAY()) | H17: =IF(C17="","",IF(G17=1,"✅ Completada",IF(F17="","—",IF(F17>5,"🟢 En tiempo",IF(F17>=1,"🟡 Por vencer","🔴 Vencida")))))
B18: 9 | F18: =IF(E18="","",E18-TODAY()) | H18: =IF(C18="","",IF(G18=1,"✅ Completada",IF(F18="","—",IF(F18>5,"🟢 En tiempo",IF(F18>=1,"🟡 Por vencer","🔴 Vencida")))))
B19: 10 | F19: =IF(E19="","",E19-TODAY()) | H19: =IF(C19="","",IF(G19=1,"✅ Completada",IF(F19="","—",IF(F19>5,"🟢 En tiempo",IF(F19>=1,"🟡 Por vencer","🔴 Vencida")))))
B20: 11 | F20: =IF(E20="","",E20-TODAY()) | H20: =IF(C20="","",IF(G20=1,"✅ Completada",IF(F20="","—",IF(F20>5,"🟢 En tiempo",IF(F20>=1,"🟡 Por vencer","🔴 Vencida")))))
B21: 12 | F21: =IF(E21="","",E21-TODAY()) | H21: =IF(C21="","",IF(G21=1,"✅ Completada",IF(F21="","—",IF(F21>5,"🟢 En tiempo",IF(F21>=1,"🟡 Por vencer","🔴 Vencida")))))
... B24: 15 | F24: =IF(E24="","",E24-TODAY()) | H24: =IF(C24="","",IF(G24=1,"✅ Completada",IF(F24="","—",IF(F24>5,"🟢 En tiempo",IF(F24>=1,"🟡 Por vencer","🔴 Vencida")))))
B26: 📌 INSTRUCCIONES DE USO
B27: 1️⃣ Escriba el ID del proyecto arriba (celda E5) → Ej: P1, P2, P3…
B28: 2️⃣ Complete las columnas AMARILLAS: Nombre de Tarea, Fecha Inicio, Fecha Fin, % Avance
B29: 3️⃣ Las columnas GRISES se calcularán automáticamente:
B30: • Días Restantes = Fecha Fin - Hoy
B31: • Estado: 🟢 En tiempo (>5 días) · 🟡 Por vencer (1-5 días) · 🔴 Vencida (<=0 días) · ✅ Completada (100%)
B32: 4️⃣ Una vez completadas las tareas, copie esta información a la hoja del proyecto correspondiente (P1, P2, P3…)
B34: 💡 TIP: Puede agregar o quitar filas según necesite más o menos tareas.

Sheet Dashboard
B2: 📊 PORTAFOLIO OTIC — DASHBOARD DE GESTIÓN
B5: ▶ PROYECTO: | C5: P1 | D5: ← Escriba el ID (P1, P2 ... P29)
B7: =IFERROR(C5&" | "&VLOOKUP(C5,'Data Original'!A:AC,3,0),"Proyecto no encontrado") -> P1 | DARUMA
B9: ⏱ VELOCÍMETROS — SEMÁFORO DE FECHAS CLAVE
B10: INDICADOR | C10: FECHA META | E10: DÍAS | F10: ESTADO / SEMÁFORO
B11: 📄 ENTREGA ABOGADO OTIC 6 días antes de Mesa | C11: =IFERROR(TEXT(VLOOKUP(C5,'Data Original'!A:AC,15,0),"DD/MM/YYYY"),"N/D") -> 20/05/2026 | E11: =IFERROR(VLOOKUP(C5,'Data Original'!A:AC,16,0),"—") -> 65 | F11: =IFERROR(IF(ISNUMBER(E11),IF(E11>=20,"✅ EN TIEMPO",IF(E11>=7,"⚠ ALERTA","🔴 CRÍTICO")),"—"),"") -> ✅ EN TIEMPO
B12: 🤝 MESA DE TRABAJO Fecha comprometida | C12: =IFERROR(TEXT(VLOOKUP(C5,'Data Original'!A:AC,17,0),"DD/MM/YYYY"),"N/D") -> 26/08/2026 | E12: =IFERROR(VLOOKUP(C5,'Data Original'!A:AC,19,0),"—") -> 74 | F12: =IFERROR(IF(ISNUMBER(E12),IF(E12>=20,"✅ EN TIEMPO",IF(E12>=7,"⚠ ALERTA","🔴 CRÍTICO")),"—"),"") -> ✅ EN TIEMPO
B13: ⚡ RADICACIÓN CONTRATACIÓN ⚠ CRÍTICA — umbral 20 días | C13: =IFERROR(TEXT(VLOOKUP(C5,'Data Original'!A:AC,20,0),"DD/MM/YYYY"),"N/D") -> 22/06/2026 | E13: =IFERROR(VLOOKUP(C5,'Data Original'!A:AC,22,0),"—") -> 88 | F13: =IFERROR(IF(ISNUMBER(E13),IF(E13>=30,"✅ EN TIEMPO",IF(E13>=21,"⚠ ALERTA","🔴 CRÍTICO")),"—"),"") -> ✅ EN TIEMPO
B15: 📋 DATOS DEL PROYECTO & 👥 EQUIPO OTIC
B16: 📋 Datos del Proyecto | E16: 👥 Equipo OTIC Asignado
B17: ID Proyecto | C17: =C5 -> P1 | E17: Supervisor
B18: Nombre | C18: =IFERROR(VLOOKUP(C5,'Data Original'!A:AC,3,0),"N/D") -> DARUMA | E18: =IFERROR(VLOOKUP(C5,'Data Original'!A:AC,28,0),"N/D") -> Mayerly Benavides
B19: Modalidad | C19: =IFERROR(VLOOKUP(C5,'Data Original'!A:AC,5,0),"N/D") -> 12.4-CONTRATACIÓN DIRECTA-CONVENIOS O CONTRATOS INTERADMINISTRATIVOS | E19: Estructurador
B20: Estado | C20: =IFERROR(VLOOKUP(C5,'Data Original'!A:AC,2,0),"N/D") -> En Progreso | E20: =IFERROR(VLOOKUP(C5,'Data Original'!A:AC,25,0),"N/D") -> Mayerly Benavides
B21: Valor Proyecto | C21: =IFERROR(TEXT(VLOOKUP(C5,'Data Original'!A:AC,12,0),"$#,##0"),"N/D") -> $15000000,0 | E21: Abogado OTIC
B22: Abogado OTIC | C22: =IFERROR(VLOOKUP(C5,'Data Original'!A:AC,26,0),"N/D") -> Carlos Gonzales | E22: =IFERROR(VLOOKUP(C5,'Data Original'!A:AC,26,0),"N/D") -> Carlos Gonzales
B24: 📝 TAREAS COMPROMETIDAS POR EL SUPERVISOR
B25: # | C25: TAREA | D25: F. INICIO | E25: F. FIN | F25: DÍAS REST. | G25: % AVANCE | H25: ESTADO
B26: =IF('P1'!A2=C5,ROW()-25,"") | C26: =IF('P1'!A2=C5,IF('P1'!C2="","",'P1'!C2),"") | D26: =IF('P1'!A2=C5,IF('P1'!D2="","",TEXT('P1'!D2,"DD/MM/YY")),"") | E26: =IF('P1'!A2=C5,IF('P1'!E2="","",TEXT('P1'!E2,"DD/MM/YY")),"") | F26: =IF('P1'!A2=C5,IF('P1'!F2="","",'P1'!F2),"") | G26: =IF('P1'!A2=C5,IF('P1'!H2="","",'P1'!H2),"") | H26: =IF('P1'!A2=C5,IF('P1'!C2=""," ",IF('P1'!H2=1,"✅ Completada",IF('P1'!F2="","—",IF('P1'!F2>5,"🟢 En tiempo",IF('P1'!F2>=1,"🟡 Por vencer","🔴 Vencida")))))," ")
B27: =IF('P1'!A3=C5,ROW()-25,"") | C27: =IF('P1'!A3=C5,IF('P1'!C3="","",'P1'!C3),"") | D27: =IF('P1'!A3=C5,IF('P1'!D3="","",TEXT('P1'!D3,"DD/MM/YY")),"") | E27: =IF('P1'!A3=C5,IF('P1'!E3="","",TEXT('P1'!E3,"DD/MM/YY")),"") | F27: =IF('P1'!A3=C5,IF('P1'!F3="","",'P1'!F3),"") | G27: =IF('P1'!A3=C5,IF('P1'!H3="","",'P1'!H3),"") | H27: =IF('P1'!A3=C5,IF('P1'!C3=""," ",IF('P1'!H3=1,"✅ Completada",IF('P1'!F3="","—",IF('P1'!F3>5,"🟢 En tiempo",IF('P1'!F3>=1,"🟡 Por vencer","🔴 Vencida")))))," ")
B28: =IF('P1'!A4=C5,ROW()-25,"") | C28: =IF('P1'!A4=C5,IF('P1'!C4="","",'P1'!C4),"") | D28: =IF('P1'!A4=C5,IF('P1'!D4="","",TEXT('P1'!D4,"DD/MM/YY")),"") | E28: =IF('P1'!A4=C5,IF('P1'!E4="","",TEXT('P1'!E4,"DD/MM/YY")),"") | F28: =IF('P1'!A4=C5,IF('P1'!F4="","",'P1'!F4),"") | G28: =IF('P1'!A4=C5,IF('P1'!H4="","",'P1'!H4),"") | H28: =IF('P1'!A4=C5,IF('P1'!C4=""," ",IF('P1'!H4=1,"✅ Completada",IF('P1'!F4="","—",IF('P1'!F4>5,"🟢 En tiempo",IF('P1'!F4>=1,"🟡 Por vencer","🔴 Vencida")))))," ")
B29: =IF('P1'!A5=C5,ROW()-25,"") | C29: =IF('P1'!A5=C5,IF('P1'!C5="","",'P1'!C5),"") | D29: =IF('P1'!A5=C5,IF('P1'!D5="","",TEXT('P1'!D5,"DD/MM/YY")),"") | E29: =IF('P1'!A5=C5,IF('P1'!E5="","",TEXT('P1'!E5,"DD/MM/YY")),"") | F29: =IF('P1'!A5=C5,IF('P1'!F5="","",'P1'!F5),"") | G29: =IF('P1'!A5=C5,IF('P1'!H5="","",'P1'!H5),"") | H29: =IF('P1'!A5=C5,IF('P1'!C5=""," ",IF('P1'!H5=1,"✅ Completada",IF('P1'!F5="","—",IF('P1'!F5>5,"🟢 En tiempo",IF('P1'!F5>=1,"🟡 Por vencer","🔴 Vencida")))))," ")
B30: =IF('P1'!A6=C5,ROW()-25,"") | C30: =IF('P1'!A6=C5,IF('P1'!C6="","",'P1'!C6),"") | D30: =IF('P1'!A6=C5,IF('P1'!D6="","",TEXT('P1'!D6,"DD/MM/YY")),"") | E30: =IF('P1'!A6=C5,IF('P1'!E6="","",TEXT('P1'!E6,"DD/MM/YY")),"") | F30: =IF('P1'!A6=C5,IF('P1'!F6="","",'P1'!F6),"") | G30: =IF('P1'!A6=C5,IF('P1'!H6="","",'P1'!H6),"") | H30: =IF('P1'!A6=C5,IF('P1'!C6=""," ",IF('P1'!H6=1,"✅ Completada",IF('P1'!F6="","—",IF('P1'!F6>5,"🟢 En tiempo",IF('P1'!F6>=1,"🟡 Por vencer","🔴 Vencida")))))," ")
B31: =IF('P1'!A7=C5,ROW()-25,"") | C31: =IF('P1'!A7=C5,IF('P1'!C7="","",'P1'!C7),"") | D31: =IF('P1'!A7=C5,IF('P1'!D7="","",TEXT('P1'!D7,"DD/MM/YY")),"") | E31: =IF('P1'!A7=C5,IF('P1'!E7="","",TEXT('P1'!E7,"DD/MM/YY")),"") | F31: =IF('P1'!A7=C5,IF('P1'!F7="","",'P1'!F7),"") | G31: =IF('P1'!A7=C5,IF('P1'!H7="","",'P1'!H7),"") | H31: =IF('P1'!A7=C5,IF('P1'!C7=""," ",IF('P1'!H7=1,"✅ Completada",IF('P1'!F7="","—",IF('P1'!F7>5,"🟢 En tiempo",IF('P1'!F7>=1,"🟡 Por vencer","🔴 Vencida")))))," ")
B32: =IF('P1'!A8=C5,ROW()-25,"") | C32: =IF('P1'!A8=C5,IF('P1'!C8="","",'P1'!C8),"") | D32: =IF('P1'!A8=C5,IF('P1'!D8="","",TEXT('P1'!D8,"DD/MM/YY")),"") | E32: =IF('P1'!A8=C5,IF('P1'!E8="","",TEXT('P1'!E8,"DD/MM/YY")),"") | F32: =IF('P1'!A8=C5,IF('P1'!F8="","",'P1'!F8),"") | G32: =IF('P1'!A8=C5,IF('P1'!H8="","",'P1'!H8),"") | H32: =IF('P1'!A8=C5,IF('P1'!C8=""," ",IF('P1'!H8=1,"✅ Completada",IF('P1'!F8="","—",IF('P1'!F8>5,"🟢 En tiempo",IF('P1'!F8>=1,"🟡 Por vencer","🔴 Vencida")))))," ")
B33: =IF('P1'!A9=C5,ROW()-25,"") | C33: =IF('P1'!A9=C5,IF('P1'!C9="","",'P1'!C9),"") | D33: =IF('P1'!A9=C5,IF('P1'!D9="","",TEXT('P1'!D9,"DD/MM/YY")),"") | E33: =IF('P1'!A9=C5,IF('P1'!E9="","",TEXT('P1'!E9,"DD/MM/YY")),"") | F33: =IF('P1'!A9=C5,IF('P1'!F9="","",'P1'!F9),"") | G33: =IF('P1'!A9=C5,IF('P1'!H9="","",'P1'!H9),"") | H33: =IF('P1'!A9=C5,IF('P1'!C9=""," ",IF('P1'!H9=1,"✅ Completada",IF('P1'!F9="","—",IF('P1'!F9>5,"🟢 En tiempo",IF('P1'!F9>=1,"🟡 Por vencer","🔴 Vencida")))))," ")
B34: =IF('P1'!A10=C5,ROW()-25,"") | C34: =IF('P1'!A10=C5,IF('P1'!C10="","",'P1'!C10),"") | D34: =IF('P1'!A10=C5,IF('P1'!D10="","",TEXT('P1'!D10,"DD/MM/YY")),"") | E34: =IF('P1'!A10=C5,IF('P1'!E10="","",TEXT('P1'!E10,"DD/MM/YY")),"") | F34: =IF('P1'!A10=C5,IF('P1'!F10="","",'P1'!F10),"") | G34: =IF('P1'!A10=C5,IF('P1'!H10="","",'P1'!H10),"") | H34: =IF('P1'!A10=C5,IF('P1'!C10=""," ",IF('P1'!H10=1,"✅ Completada",IF('P1'!F10="","—",IF('P1'!F10>5,"🟢 En tiempo",IF('P1'!F10>=1,"🟡 Por vencer","🔴 Vencida")))))," ")
B35: =IF('P1'!A11=C5,ROW()-25,"") | C35: =IF('P1'!A11=C5,IF('P1'!C11="","",'P1'!C11),"") | D35: =IF('P1'!A11=C5,IF('P1'!D11="","",TEXT('P1'!D11,"DD/MM/YY")),"") | E35: =IF('P1'!A11=C5,IF('P1'!E11="","",TEXT('P1'!E11,"DD/MM/YY")),"") | F35: =IF('P1'!A11=C5,IF('P1'!F11="","",'P1'!F11),"") | G35: =IF('P1'!A11=C5,IF('P1'!H11="","",'P1'!H11),"") | H35: =IF('P1'!A11=C5,IF('P1'!C11=""," ",IF('P1'!H11=1,"✅ Completada",IF('P1'!F11="","—",IF('P1'!F11>5,"🟢 En tiempo",IF('P1'!F11>=1,"🟡 Por vencer","🔴 Vencida")))))," ")
B36: =IF('P1'!A12=C5,ROW()-25,"") | C36: =IF('P1'!A12=C5,IF('P1'!C12="","",'P1'!C12),"") | D36: =IF('P1'!A12=C5,IF('P1'!D12="","",TEXT('P1'!D12,"DD/MM/YY")),"") | E36: =IF('P1'!A12=C5,IF('P1'!E12="","",TEXT('P1'!E12,"DD/MM/YY")),"") | F36: =IF('P1'!A12=C5,IF('P1'!F12="","",'P1'!F12),"") | G36: =IF('P1'!A12=C5,IF('P1'!H12="","",'P1'!H12),"") | H36: =IF('P1'!A12=C5,IF('P1'!C12=""," ",IF('P1'!H12=1,"✅ Completada",IF('P1'!F12="","—",IF('P1'!F12>5,"🟢 En tiempo",IF('P1'!F12>=1,"🟡 Por vencer","🔴 Vencida")))))," ")
B37: =IF('P1'!A13=C5,ROW()-25,"") | C37: =IF('P1'!A13=C5,IF('P1'!C13="","",'P1'!C13),"") | D37: =IF('P1'!A13=C5,IF('P1'!D13="","",TEXT('P1'!D13,"DD/MM/YY")),"") | E37: =IF('P1'!A13=C5,IF('P1'!E13="","",TEXT('P1'!E13,"DD/MM/YY")),"") | F37: =IF('P1'!A13=C5,IF('P1'!F13="","",'P1'!F13),"") | G37: =IF('P1'!A13=C5,IF('P1'!H13="","",'P1'!H13),"") | H37: =IF('P1'!A13=C5,IF('P1'!C13=""," ",IF('P1'!H13=1,"✅ Completada",IF('P1'!F13="","—",IF('P1'!F13>5,"🟢 En tiempo",IF('P1'!F13>=1,"🟡 Por vencer","🔴 Vencida")))))," ")
B38: =IF('P1'!A14=C5,ROW()-25,"") | C38: =IF('P1'!A14=C5,IF('P1'!C14="","",'P1'!C14),"") | D38: =IF('P1'!A14=C5,IF('P1'!D14="","",TEXT('P1'!D14,"DD/MM/YY")),"") | E38: =IF('P1'!A14=C5,IF('P1'!E14="","",TEXT('P1'!E14,"DD/MM/YY")),"") | F38: =IF('P1'!A14=C5,IF('P1'!F14="","",'P1'!F14),"") | G38: =IF('P1'!A14=C5,IF('P1'!H14="","",'P1'!H14),"") | H38: =IF('P1'!A14=C5,IF('P1'!C14=""," ",IF('P1'!H14=1,"✅ Completada",IF('P1'!F14="","—",IF('P1'!F14>5,"🟢 En tiempo",IF('P1'!F14>=1,"🟡 Por vencer","🔴 Vencida")))))," ")
B39: =IF('P1'!A15=C5,ROW()-25,"") | C39: =IF('P1'!A15=C5,IF('P1'!C15="","",'P1'!C15),"") | D39: =IF('P1'!A15=C5,IF('P1'!D15="","",TEXT('P1'!D15,"DD/MM/YY")),"") | E39: =IF('P1'!A15=C5,IF('P1'!E15="","",TEXT('P1'!E15,"DD/MM/YY")),"") | F39: =IF('P1'!A15=C5,IF('P1'!F15="","",'P1'!F15),"") | G39: =IF('P1'!A15=C5,IF('P1'!H15="","",'P1'!H15),"") | H39: =IF('P1'!A15=C5,IF('P1'!C15=""," ",IF('P1'!H15=1,"✅ Completada",IF('P1'!F15="","—",IF('P1'!F15>5,"🟢 En tiempo",IF('P1'!F15>=1,"🟡 Por vencer","🔴 Vencida")))))," ")
B40: =IF('P1'!A16=C5,ROW()-25,"") | C40: =IF('P1'!A16=C5,IF('P1'!C16="","",'P1'!C16),"") | D40: =IF('P1'!A16=C5,IF('P1'!D16="","",TEXT('P1'!D16,"DD/MM/YY")),"") | E40: =IF('P1'!A16=C5,IF('P1'!E16="","",TEXT('P1'!E16,"DD/MM/YY")),"") | F40: =IF('P1'!A16=C5,IF('P1'!F16="","",'P1'!F16),"") | G40: =IF('P1'!A16=C5,IF('P1'!H16="","",'P1'!H16),"") | H40: =IF('P1'!A16=C5,IF('P1'!C16=""," ",IF('P1'!H16=1,"✅ Completada",IF('P1'!F16="","—",IF('P1'!F16>5,"🟢 En tiempo",IF('P1'!F16>=1,"🟡 Por vencer","🔴 Vencida")))))," ")
B42: PROGRESO GENERAL: | D42: =IF('P1'!A2=C5,TEXT(AVERAGE('P1'!H2:H16),"0%")&" ("&COUNTIF('P1'!H2:H16,1)&"/"&COUNTA('P1'!C2:C16)&" tareas)","") | G42: =IF('P1'!A2=C5,IF(AVERAGE('P1'!H2:H16)=1,"✅ COMPLETADO",IF(AVERAGE('P1'!H2:H16)>=0.7,"🟢 BUEN RITMO",IF(AVERAGE('P1'!H2:H16)>=0.4,"🟡 EN PROGRESO","🔴 REZAGADO"))),"")
B44: ℹ️ Las tareas se cargan desde la hoja del proyecto (P1, P2…) · Semáforo: 🟢 >5d | 🟡 1-5d | 🔴 Vencida | ✅ Completada

Sheet P1
A1: 📋 PLAN DE TRABAJO — P1: DARUMA QUITAR
A2: ⚠️ Campos AMARILLOS: ingresar datos | Campos GRISES: calculados automáticamente | % Avance: 0-100
A3: # | B3: ID | C3: FASE | D3: NOMBRE DE LA TAREA | E3: F. INICIO | F3: F. FIN COMPROMETIDA | G3: DÍAS REST. | H3: % AVANCE | I3: ESTADO | J3: PROGRESO
A4: 1 | B4: P1 | C4: Estructuracion | D4: Asignacion proyecto | E4: 46055 | F4: 46065 | G4: =IF(F4="","",F4-TODAY()) -> -7 | H4: 38 | I4: =IF(D4="","",IF(H4=100,"✅ Completada",IF(F4="","",IF(F4<TODAY(),"🔴 Vencida",IF(G4<=5,"🟡 Por vencer","🟢 En tiempo"))))) -> 🔴 Vencida | J4: =IF(H4="","",REPT("█",ROUND(H4/10,0))&" "&H4&"%") -> ████ 38%
A5: 2 | B5: P1 | C5: Estructuracion | D5: Estudio previo | E5: 46056 | F5: 46059 | G5: =IF(F5="","",F5-TODAY()) -> -13 | H5: 16 | I5: =IF(D5="","",IF(H5=100,"✅ Completada",IF(F5="","",IF(F5<TODAY(),"🔴 Vencida",IF(G5<=5,"🟡 Por vencer","🟢 En tiempo"))))) -> 🔴 Vencida | J5: =IF(H5="","",REPT("█",ROUND(H5/10,0))&" "&H5&"%") -> ██ 16%
A6: 3 | B6: P1 | C6: Estructuracion | D6: Estudio de sector | E6: 46057 | F6: 46058 | G6: =IF(F6="","",F6-TODAY()) -> -14 | H6: 9 | I6: =IF(D6="","",IF(H6=100,"✅ Completada",IF(F6="","",IF(F6<TODAY(),"🔴 Vencida",IF(G6<=5,"🟡 Por vencer","🟢 En tiempo"))))) -> 🔴 Vencida | J6: =IF(H6="","",REPT("█",ROUND(H6/10,0))&" "&H6&"%") -> █ 9%
A7: 4 | B7: P1 | C7: Estructuracion | D7: Estudio de mercado | E7: 46058 | F7: 46062 | G7: =IF(F7="","",F7-TODAY()) -> -10 | H7: 20 | I7: =IF(D7="","",IF(H7=100,"✅ Completada",IF(F7="","",IF(F7<TODAY(),"🔴 Vencida",IF(G7<=5,"🟡 Por vencer","🟢 En tiempo"))))) -> 🔴 Vencida | J7: =IF(H7="","",REPT("█",ROUND(H7/10,0))&" "&H7&"%") -> ██ 20%
A8: 5 | B8: P1 | C8: Estructuracion | D8: Ficha técnica | E8: 46059 | F8: 46066 | G8: =IF(F8="","",F8-TODAY()) -> -6 | H8: 66 | I8: =IF(D8="","",IF(H8=100,"✅ Completada",IF(F8="","",IF(F8<TODAY(),"🔴 Vencida",IF(G8<=5,"🟡 Por vencer","🟢 En tiempo"))))) -> 🔴 Vencida | J8: =IF(H8="","",REPT("█",ROUND(H8/10,0))&" "&H8&"%") -> ███████ 66%
A9: 6 | B9: P1 | C9: Estructuracion | D9: Tarea 6 | E9: 46060 | F9: 46068 | G9: =IF(F9="","",F9-TODAY()) -> -4 | H9: 75 | I9: =IF(D9="","",IF(H9=100,"✅ Completada",IF(F9="","",IF(F9<TODAY(),"🔴 Vencida",IF(G9<=5,"🟡 Por vencer","🟢 En tiempo"))))) -> 🔴 Vencida | J9: =IF(H9="","",REPT("█",ROUND(H9/10,0))&" "&H9&"%") -> ████████ 75%
A10: 7 | B10: P1 | C10: Estructuracion | D10: Tarea 7 | E10: 46061 | F10: 46066 | G10: =IF(F10="","",F10-TODAY()) -> -6 | H10: 62 | I10: =IF(D10="","",IF(H10=100,"✅ Completada",IF(F10="","",IF(F10<TODAY(),"🔴 Vencida",IF(G10<=5,"🟡 Por vencer","🟢 En tiempo"))))) -> 🔴 Vencida | J10: =IF(H10="","",REPT("█",ROUND(H10/10,0))&" "&H10&"%") -> ██████ 62%
A11: 8 | B11: P1 | C11: Estructuracion | D11: Tarea 8 | E11: 46062 | F11: 46066 | G11: =IF(F11="","",F11-TODAY()) -> -6 | H11: 12 | I11: =IF(D11="","",IF(H11=100,"✅ Completada",IF(F11="","",IF(F11<TODAY(),"🔴 Vencida",IF(G11<=5,"🟡 Por vencer","🟢 En tiempo"))))) -> 🔴 Vencida | J11: =IF(H11="","",REPT("█",ROUND(H11/10,0))&" "&H11&"%") -> █ 12%
A12: 9 | B12: P1 | C12: Estructuracion | D12: Tarea 9 | E12: 46063 | F12: 46072 | G12: =IF(F12="","",F12-TODAY()) -> 0 | H12: 57 | I12: =IF(D12="","",IF(H12=100,"✅ Completada",IF(F12="","",IF(F12<TODAY(),"🔴 Vencida",IF(G12<=5,"🟡 Por vencer","🟢 En tiempo"))))) -> 🟡 Por vencer | J12: =IF(H12="","",REPT("█",ROUND(H12/10,0))&" "&H12&"%") -> ██████ 57%
A13: 10 | B13: P1 | C13: Estructuracion | D13: Tarea 10 | E13: 46064 | F13: 46068 | G13: =IF(F13="","",F13-TODAY()) -> -4 | H13: 33 | I13: =IF(D13="","",IF(H13=100,"✅ Completada",IF(F13="","",IF(F13<TODAY(),"🔴 Vencida",IF(G13<=5,"🟡 Por vencer","🟢 En tiempo"))))) -> 🔴 Vencida | J13: =IF(H13="","",REPT("█",ROUND(H13/10,0))&" "&H13&"%") -> ███ 33%
A14: 11 | B14: P1 | C14: Estructuracion | D14: Gestionar y escalar impedimentos con las áreas o responsables correspondientes lo que conlleva a un apoyo en la interacción con otras áreas | E14: 46065 | F14: 46070 | G14: =IF(F14="","",F14-TODAY()) -> -2 | H14: 80 | I14: =IF(D14="","",IF(H14=100,"✅ Completada",IF(F14="","",IF(F14<TODAY(),"🔴 Vencida",IF(G14<=5,"🟡 Por vencer","🟢 En tiempo"))))) -> 🔴 Vencida | J14: =IF(H14="","",REPT("█",ROUND(H14/10,0))&" "&H14&"%") -> ████████ 80%
A15: 12 | B15: P1 | G15: =IF(F15="","",F15-TODAY()) | I15: =IF(D15="","",IF(H15=100,"✅ Completada",IF(F15="","",IF(F15<TODAY(),"🔴 Vencida",IF(G15<=5,"🟡 Por vencer","🟢 En tiempo"))))) | J15: =IF(H15="","",REPT("█",ROUND(H15/10,0))&" "&H15&"%")
A16: 13 | B16: P1 | G16: =IF(F16="","",F16-TODAY()) | I16: =IF(D16="","",IF(H16=100,"✅ Completada",IF(F16="","",IF(F16<TODAY(),"🔴 Vencida",IF(G16<=5,"🟡 Por vencer","🟢 En tiempo"))))) | J16: =IF(H16="","",REPT("█",ROUND(H16/10,0))&" "&H16&"%")
A17: 14 | B17: P1 | G17: =IF(F17="","",F17-TODAY()) | I17: =IF(D17="","",IF(H17=100,"✅ Completada",IF(F17="","",IF(F17<TODAY(),"🔴 Vencida",IF(G17<=5,"🟡 Por vencer","🟢 En tiempo"))))) | J17: =IF(H17="","",REPT("█",ROUND(H17/10,0))&" "&H17&"%")
A18: 15 | B18: P1 | G18: =IF(F18="","",F18-TODAY()) | I18: =IF(D18="","",IF(H18=100,"✅ Completada",IF(F18="","",IF(F18<TODAY(),"🔴 Vencida",IF(G18<=5,"🟡 Por vencer","🟢 En tiempo"))))) | J18: =IF(H18="","",REPT("█",ROUND(H18/10,0))&" "&H18&"%")
A19: 📊 PROGRESO GENERAL DEL PROYECTO | H19: =IFERROR(AVERAGE(IF(H4:H18<>"",H4:H18)),0) -> 0 | I19: =COUNTIF(I4:I18,"✅ Completada")&" de "&COUNTA(D4:D18)&" tareas completadas" -> 0 de 11 tareas completadas

Sheet P2
A1: 📋 PLAN DE TRABAJO — P2: EQUIPOS ACTIVOS DE RED ETAPA 3
A2: ⚠️ Campos AMARILLOS: ingresar datos | Campos GRISES: calculados automáticamente | % Avance: 0-100
A3: # | B3: ID | C3: FASE | D3: NOMBRE DE LA TAREA | E3: F. INICIO | F3: F. FIN COMPROMETIDA | G3: DÍAS REST. | H3: % AVANCE | I3: ESTADO | J3: PROGRESO
A4: 1 | B4: P2 | C4: Estructuracion | D4: Análisis de requerimientos | E4: 46071.259 | F4: 46083.259 | G4: =IF(F4="","",F4-TODAY()) -> 11.258691 | H4: 85 | I4: =IF(D4="","",IF(H4=100,"✅ Completada",IF(F4="","",IF(F4<TODAY(),"🔴 Vencida",IF(G4<=5,"🟡 Por vencer","🟢 En tiempo"))))) -> 🟢 En tiempo | J4: =IF(H4="","",REPT("█",ROUND(H4/10,0))&" "&H4&"%") -> █████████ 85%
A5: 2 | B5: P2 | C5: Estructuracion | D5: Elaboración términos de referencia | E5: 46074.259 | F5: 46081.259 | G5: =IF(F5="","",F5-TODAY()) -> 9.2586909 | H5: 60 | I5: =IF(D5="","",IF(H5=100,"✅ Completada",IF(F5="","",IF(F5<TODAY(),"🔴 Vencida",IF(G5<=5,"🟡 Por vencer","🟢 En tiempo"))))) -> 🟢 En tiempo | J5: =IF(H5="","",REPT("█",ROUND(H5/10,0))&" "&H5&"%") -> ██████ 60%
A6: 3 | B6: P2 | C6: Estructuracion | D6: Estudio de mercado | E6: 46077.259 | F6: 46092.259 | G6: =IF(F6="","",F6-TODAY()) -> 20.258691 | H6: 40 | I6: =IF(D6="","",IF(H6=100,"✅ Completada",IF(F6="","",IF(F6<TODAY(),"🔴 Vencida",IF(G6<=5,"🟡 Por vencer","🟢 En tiempo"))))) -> 🟢 En tiempo | J6: =IF(H6="","",REPT("█",ROUND(H6/10,0))&" "&H6&"%") -> ████ 40%
A7: 4 | B7: P2 | C7: Estructuracion | D7: Certificado de disponibilidad presupuestal | E7: 46080.259 | F7: 46095.259 | G7: =IF(F7="","",F7-TODAY()) -> 23.258691 | H7: 25 | I7: =IF(D7="","",IF(H7=100,"✅ Completada",IF(F7="","",IF(F7<TODAY(),"🔴 Vencida",IF(G7<=5,"🟡 Por vencer","🟢 En tiempo"))))) -> 🟢 En tiempo | J7: =IF(H7="","",REPT("█",ROUND(H7/10,0))&" "&H7&"%") -> ███ 25%
A8: 5 | B8: P2 | C8: Estructuracion | D8: Revisión jurídica | E8: 46083.259 | F8: 46089.259 | G8: =IF(F8="","",F8-TODAY()) -> 17.258691 | H8: 10 | I8: =IF(D8="","",IF(H8=100,"✅ Completada",IF(F8="","",IF(F8<TODAY(),"🔴 Vencida",IF(G8<=5,"🟡 Por vencer","🟢 En tiempo"))))) -> 🟢 En tiempo | J8: =IF(H8="","",REPT("█",ROUND(H8/10,0))&" "&H8&"%") -> █ 10%
A9: 6 | B9: P2 | C9: Estructuracion | D9: Publicación SECOP | E9: 46086.259 | F9: 46093.259 | G9: =IF(F9="","",F9-TODAY()) -> 21.258691 | H9: 5 | I9: =IF(D9="","",IF(H9=100,"✅ Completada",IF(F9="","",IF(F9<TODAY(),"🔴 Vencida",IF(G9<=5,"🟡 Por vencer","🟢 En tiempo"))))) -> 🟢 En tiempo | J9: =IF(H9="","",REPT("█",ROUND(H9/10,0))&" "&H9&"%") -> █ 5%
A10: 7 | B10: P2 | C10: Estructuracion | D10: Recepción ofertas | E10: 46089.259 | F10: 46100.259 | G10: =IF(F10="","",F10-TODAY()) -> 28.258691 | H10: 0 | I10: =IF(D10="","",IF(H10=100,"✅ Completada",IF(F10="","",IF(F10<TODAY(),"🔴 Vencida",IF(G10<=5,"🟡 Por vencer","🟢 En tiempo"))))) -> 🟢 En tiempo | J10: =IF(H10="","",REPT("█",ROUND(H10/10,0))&" "&H10&"%") -> 0%
A11: 8 | B11: P2 | C11: Estructuracion | D11: Evaluación técnica | E11: 46092.259 | F11: 46100.259 | G11: =IF(F11="","",F11-TODAY()) -> 28.258691 | H11: 0 | I11: =IF(D11="","",IF(H11=100,"✅ Completada",IF(F11="","",IF(F11<TODAY(),"🔴 Vencida",IF(G11<=5,"🟡 Por vencer","🟢 En tiempo"))))) -> 🟢 En tiempo | J11: =IF(H11="","",REPT("█",ROUND(H11/10,0))&" "&H11&"%") -> 0%
A12: 9 | B12: P2 | C12: Estructuracion | D12: Evaluación económica | E12: 46095.259 | F12: 46107.259 | G12: =IF(F12="","",F12-TODAY()) -> 35.258691 | H12: 0 | I12: =IF(D12="","",IF(H12=100,"✅ Completada",IF(F12="","",IF(F12<TODAY(),"🔴 Vencida",IF(G12<=5,"🟡 Por vencer","🟢 En tiempo"))))) -> 🟢 En tiempo | J12: =IF(H12="","",REPT("█",ROUND(H12/10,0))&" "&H12&"%") -> 0%
A13: 10 | B13: P2 | C13: Estructuracion | D13: Informe de evaluación | E13: 46098.259 | F13: 46106.259 | G13: =IF(F13="","",F13-TODAY()) -> 34.258691 | H13: 0 | I13: =IF(D13="","",IF(H13=100,"✅ Completada",IF(F13="","",IF(F13<TODAY(),"🔴 Vencida",IF(G13<=5,"🟡 Por vencer","🟢 En tiempo"))))) -> 🟢 En tiempo | J13: =IF(H13="","",REPT("█",ROUND(H13/10,0))&" "&H13&"%") -> 0%
A14: 11 | B14: P2 | C14: Estructuracion | D14: Adjudicación | E14: 46101.259 | F14: 46110.259 | G14: =IF(F14="","",F14-TODAY()) -> 38.258691 | H14: 0 | I14: =IF(D14="","",IF(H14=100,"✅ Completada",IF(F14="","",IF(F14<TODAY(),"🔴 Vencida",IF(G14<=5,"🟡 Por vencer","🟢 En tiempo"))))) -> 🟢 En tiempo | J14: =IF(H14="","",REPT("█",ROUND(H14/10,0))&" "&H14&"%") -> 0%
A15: 12 | B15: P2 | G15: =IF(F15="","",F15-TODAY()) | I15: =IF(D15="","",IF(H15=100,"✅ Completada",IF(F15="","",IF(F15<TODAY(),"🔴 Vencida",IF(G15<=5,"🟡 Por vencer","🟢 En tiempo"))))) | J15: =IF(H15="","",REPT("█",ROUND(H15/10,0))&" "&H15&"%")
A16: 13 | B16: P2 | G16: =IF(F16="","",F16-TODAY()) | I16: =IF(D16="","",IF(H16=100,"✅ Completada",IF(F16="","",IF(F16<TODAY(),"🔴 Vencida",IF(G16<=5,"🟡 Por vencer","🟢 En tiempo"))))) | J16: =IF(H16="","",REPT("█",ROUND(H16/10,0))&" "&H16&"%")
A17: 14 | B17: P2 | G17: =IF(F17="","",F17-TODAY()) | I17: =IF(D17="","",IF(H17=100,"✅ Completada",IF(F17="","",IF(F17<TODAY(),"🔴 Vencida",IF(G17<=5,"🟡 Por vencer","🟢 En tiempo"))))) | J17: =IF(H17="","",REPT("█",ROUND(H17/10,0))&" "&H17&"%")
A18: 15 | B18: P2 | G18: =IF(F18="","",F18-TODAY()) | I18: =IF(D18="","",IF(H18=100,"✅ Completada",IF(F18="","",IF(F18<TODAY(),"🔴 Vencida",IF(G18<=5,"🟡 Por vencer","🟢 En tiempo"))))) | J18: =IF(H18="","",REPT("█",ROUND(H18/10,0))&" "&H18&"%")
A19: 📊 PROGRESO GENERAL DEL PROYECTO | H19: =IFERROR(AVERAGE(IF(H4:H18<>"",H4:H18)),0) -> 0 | I19: =COUNTIF(I4:I18,"✅ Completada")&" de "&COUNTA(D4:D18)&" tareas completadas" -> 0 de 11 tareas completadas

Sheet P3
A1: 📋 PLAN DE TRABAJO — P3: GOOGLE WORKSPACE
A2: ⚠️ Campos AMARILLOS: ingresar datos | Campos GRISES: calculados automáticamente | % Avance: 0-100
A3: # | B3: ID | C3: FASE | D3: NOMBRE DE LA TAREA | E3: F. INICIO | F3: F. FIN COMPROMETIDA | G3: DÍAS REST. | H3: % AVANCE | I3: ESTADO | J3: PROGRESO
A4: 1 | B4: P3 | G4: =IF(F4="","",F4-TODAY()) | I4: =IF(D4="","",IF(H4=100,"✅ Completada",IF(F4="","",IF(F4<TODAY(),"🔴 Vencida",IF(G4<=5,"🟡 Por vencer","🟢 En tiempo"))))) | J4: =IF(H4="","",REPT("█",ROUND(H4/10,0))&" "&H4&"%")
A5: 2 | B5: P3 | G5: =IF(F5="","",F5-TODAY()) | I5: =IF(D5="","",IF(H5=100,"✅ Completada",IF(F5="","",IF(F5<TODAY(),"🔴 Vencida",IF(G5<=5,"🟡 Por vencer","🟢 En tiempo"))))) | J5: =IF(H5="","",REPT("█",ROUND(H5/10,0))&" "&H5&"%")
A6: 3 | B6: P3 | G6: =IF(F6="","",F6-TODAY()) | I6: =IF(D6="","",IF(H6=100,"✅ Completada",IF(F6="","",IF(F6<TODAY(),"🔴 Vencida",IF(G6<=5,"🟡 Por vencer","🟢 En tiempo"))))) | J6: =IF(H6="","",REPT("█",ROUND(H6/10,0))&" "&H6&"%")
A7: 4 | B7: P3 | G7: =IF(F7="","",F7-TODAY()) | I7: =IF(D7="","",IF(H7=100,"✅ Completada",IF(F7="","",IF(F7<TODAY(),"🔴 Vencida",IF(G7<=5,"🟡 Por vencer","🟢 En tiempo"))))) | J7: =IF(H7="","",REPT("█",ROUND(H7/10,0))&" "&H7&"%")
A8: 5 | B8: P3 | G8: =IF(F8="","",F8-TODAY()) | I8: =IF(D8="","",IF(H8=100,"✅ Completada",IF(F8="","",IF(F8<TODAY(),"🔴 Vencida",IF(G8<=5,"🟡 Por vencer","🟢 En tiempo"))))) | J8: =IF(H8="","",REPT("█",ROUND(H8/10,0))&" "&H8&"%")
A9: 6 | B9: P3 | G9: =IF(F9="","",F9-TODAY()) | I9: =IF(D9="","",IF(H9=100,"✅ Completada",IF(F9="","",IF(F9<TODAY(),"🔴 Vencida",IF(G9<=5,"🟡 Por vencer","🟢 En tiempo"))))) | J9: =IF(H9="","",REPT("█",ROUND(H9/10,0))&" "&H9&"%")
A10: 7 | B10: P3 | G10: =IF(F10="","",F10-TODAY()) | I10: =IF(D10="","",IF(H10=100,"✅ Completada",IF(F10="","",IF(F10<TODAY(),"🔴 Vencida",IF(G10<=5,"🟡 Por vencer","🟢 En tiempo"))))) | J10: =IF(H10="","",REPT("█",ROUND(H10/10,0))&" "&H10&"%")
A11: 8 | B11: P3 | G11: =IF(F11="","",F11-TODAY()) | I11: =IF(D11="","",IF(H11=100,"✅ Completada",IF(F11="","",IF(F11<TODAY(),"🔴 Vencida",IF(G11<=5,"🟡 Por vencer","🟢 En tiempo"))))) | J11: =IF(H11="","",REPT("█",ROUND(H11/10,0))&" "&H11&"%")
A12: 9 | B12: P3 | G12: =IF(F12="","",F12-TODAY()) | I12: =IF(D12="","",IF(H12=100,"✅ Completada",IF(F12="","",IF(F12<TODAY(),"🔴 Vencida",IF(G12<=5,"🟡 Por vencer","🟢 En tiempo"))))) | J12: =IF(H12="","",REPT("█",ROUND(H12/10,0))&" "&H12&"%")
A13: 10 | B13: P3 | G13: =IF(F13="","",F13-TODAY()) | I13: =IF(D13="","",IF(H13=100,"✅ Completada",IF(F13="","",IF(F13<TODAY(),"🔴 Vencida",IF(G13<=5,"🟡 Por vencer","🟢 En tiempo"))))) | J13: =IF(H13="","",REPT("█",ROUND(H13/10,0))&" "&H13&"%")
A14: 11 | B14: P3 | G14: =IF(F14="","",F14-TODAY()) | I14: =IF(D14="","",IF(H14=100,"✅ Completada",IF(F14="","",IF(F14<TODAY(),"🔴 Vencida",IF(G14<=5,"🟡 Por vencer","🟢 En tiempo"))))) | J14: =IF(H14="","",REPT("█",ROUND(H14/10,0))&" "&H14&"%")
A15: 12 | B15: P3 | G15: =IF(F15="","",F15-TODAY()) | I15: =IF(D15="","",IF(H15=100,"✅ Completada",IF(F15="","",IF(F15<TODAY(),"🔴 Vencida",IF(G15<=5,"🟡 Por vencer","🟢 En tiempo"))))) | J15: =IF(H15="","",REPT("█",ROUND(H15/10,0))&" "&H15&"%")
... A18: 15 | B18: P3 | G18: =IF(F18="","",F18-TODAY()) | I18: =IF(D18="","",IF(H18=100,"✅ Completada",IF(F18="","",IF(F18<TODAY(),"🔴 Vencida",IF(G18<=5,"🟡 Por vencer","🟢 En tiempo"))))) | J18: =IF(H18="","",REPT("█",ROUND(H18/10,0))&" "&H18&"%")
A19: 📊 PROGRESO GENERAL DEL PROYECTO | H19: =IFERROR(AVERAGE(IF(H4:H18<>"",H4:H18)),0) -> 0 | I19: =COUNTIF(I4:I18,"✅ Completada")&" de "&COUNTA(D4:D18)&" tareas completadas" -> 0 de 0 tareas completadas

Sheet P4
A1: 📋 PLAN DE TRABAJO — P4: NUBE
A2: ⚠️ Campos AMARILLOS: ingresar datos | Campos GRISES: calculados automáticamente | % Avance: 0-100
A3: # | B3: ID | C3: FASE | D3: NOMBRE DE LA TAREA | E3: F. INICIO | F3: F. FIN COMPROMETIDA | G3: DÍAS REST. | H3: % AVANCE | I3: ESTADO | J3: PROGRESO
A4: 1 | B4: P4 | G4: =IF(F4="","",F4-TODAY()) | I4: =IF(D4="","",IF(H4=100,"✅ Completada",IF(F4="","",IF(F4<TODAY(),"🔴 Vencida",IF(G4<=5,"🟡 Por vencer","🟢 En tiempo"))))) | J4: =IF(H4="","",REPT("█",ROUND(H4/10,0))&" "&H4&"%")
A5: 2 | B5: P4 | G5: =IF(F5="","",F5-TODAY()) | I5: =IF(D5="","",IF(H5=100,"✅ Completada",IF(F5="","",IF(F5<TODAY(),"🔴 Vencida",IF(G5<=5,"🟡 Por vencer","🟢 En tiempo"))))) | J5: =IF(H5="","",REPT("█",ROUND(H5/10,0))&" "&H5&"%")
A6: 3 | B6: P4 | G6: =IF(F6="","",F6-TODAY()) | I6: =IF(D6="","",IF(H6=100,"✅ Completada",IF(F6="","",IF(F6<TODAY(),"🔴 Vencida",IF(G6<=5,"🟡 Por vencer","🟢 En tiempo"))))) | J6: =IF(H6="","",REPT("█",ROUND(H6/10,0))&" "&H6&"%")
A7: 4 | B7: P4 | G7: =IF(F7="","",F7-TODAY()) | I7: =IF(D7="","",IF(H7=100,"✅ Completada",IF(F7="","",IF(F7<TODAY(),"🔴 Vencida",IF(G7<=5,"🟡 Por vencer","🟢 En tiempo"))))) | J7: =IF(H7="","",REPT("█",ROUND(H7/10,0))&" "&H7&"%")
A8: 5 | B8: P4 | G8: =IF(F8="","",F8-TODAY()) | I8: =IF(D8="","",IF(H8=100,"✅ Completada",IF(F8="","",IF(F8<TODAY(),"🔴 Vencida",IF(G8<=5,"🟡 Por vencer","🟢 En tiempo"))))) | J8: =IF(H8="","",REPT("█",ROUND(H8/10,0))&" "&H8&"%")
A9: 6 | B9: P4 | G9: =IF(F9="","",F9-TODAY()) | I9: =IF(D9="","",IF(H9=100,"✅ Completada",IF(F9="","",IF(F9<TODAY(),"🔴 Vencida",IF(G9<=5,"🟡 Por vencer","🟢 En tiempo"))))) | J9: =IF(H9="","",REPT("█",ROUND(H9/10,0))&" "&H9&"%")
A10: 7 | B10: P4 | G10: =IF(F10="","",F10-TODAY()) | I10: =IF(D10="","",IF(H10=100,"✅ Completada",IF(F10="","",IF(F10<TODAY(),"🔴 Vencida",IF(G10<=5,"🟡 Por vencer","🟢 En tiempo"))))) | J10: =IF(H10="","",REPT("█",ROUND(H10/10,0))&" "&H10&"%")
A11: 8 | B11: P4 | G11: =IF(F11="","",F11-TODAY()) | I11: =IF(D11="","",IF(H11=100,"✅ Completada",IF(F11="","",IF(F11<TODAY(),"🔴 Vencida",IF(G11<=5,"🟡 Por vencer","🟢 En tiempo"))))) | J11: =IF(H11="","",REPT("█",ROUND(H11/10,0))&" "&H11&"%")
A12: 9 | B12: P4 | G12: =IF(F12="","",F12-TODAY()) | I12: =IF(D12="","",IF(H12=100,"✅ Completada",IF(F12="","",IF(F12<TODAY(),"🔴 Vencida",IF(G12<=5,"🟡 Por vencer","🟢 En tiempo"))))) | J12: =IF(H12="","",REPT("█",ROUND(H12/10,0))&" "&H12&"%")
A13: 10 | B13: P4 | G13: =IF(F13="","",F13-TODAY()) | I13: =IF(D13="","",IF(H13=100,"✅ Completada",IF(F13="","",IF(F13<TODAY(),"🔴 Vencida",IF(G13<=5,"🟡 Por vencer","🟢 En tiempo"))))) | J13: =IF(H13="","",REPT("█",ROUND(H13/10,0))&" "&H13&"%")
A14: 11 | B14: P4 | G14: =IF(F14="","",F14-TODAY()) | I14: =IF(D14="","",IF(H14=100,"✅ Completada",IF(F14="","",IF(F14<TODAY(),"🔴 Vencida",IF(G14<=5,"🟡 Por vencer","🟢 En tiempo"))))) | J14: =IF(H14="","",REPT("█",ROUND(H14/10,0))&" "&H14&"%")
A15: 12 | B15: P4 | G15: =IF(F15="","",F15-TODAY()) | I15: =IF(D15="","",IF(H15=100,"✅ Completada",IF(F15="","",IF(F15<TODAY(),"🔴 Vencida",IF(G15<=5,"🟡 Por vencer","🟢 En tiempo"))))) | J15: =IF(H15="","",REPT("█",ROUND(H15/10,0))&" "&H15&"%")
... A18: 15 | B18: P4 | G18: =IF(F18="","",F18-TODAY()) | I18: =IF(D18="","",IF(H18=100,"✅ Completada",IF(F18="","",IF(F18<TODAY(),"🔴 Vencida",IF(G18<=5,"🟡 Por vencer","🟢 En tiempo"))))) | J18: =IF(H18="","",REPT("█",ROUND(H18/10,0))&" "&H18&"%")
A19: 📊 PROGRESO GENERAL DEL PROYECTO | H19: =IFERROR(AVERAGE(IF(H4:H18<>"",H4:H18)),0) -> 0 | I19: =COUNTIF(I4:I18,"✅ Completada")&" de "&COUNTA(D4:D18)&" tareas completadas" -> 0 de 0 tareas completadas

Sheet P5
A1: 📋 PLAN DE TRABAJO — P5: IMPRESIÓN ETIQUETAS
A2: ⚠️ Campos AMARILLOS: ingresar datos | Campos GRISES: calculados automáticamente | % Avance: 0-100
A3: # | B3: ID | C3: FASE | D3: NOMBRE DE LA TAREA | E3: F. INICIO | F3: F. FIN COMPROMETIDA | G3: DÍAS REST. | H3: % AVANCE | I3: ESTADO | J3: PROGRESO
A4: 1 | B4: P5 | G4: =IF(F4="","",F4-TODAY()) | I4: =IF(D4="","",IF(H4=100,"✅ Completada",IF(F4="","",IF(F4<TODAY(),"🔴 Vencida",IF(G4<=5,"🟡 Por vencer","🟢 En tiempo"))))) | J4: =IF(H4="","",REPT("█",ROUND(H4/10,0))&" "&H4&"%")
A5: 2 | B5: P5 | G5: =IF(F5="","",F5-TODAY()) | I5: =IF(D5="","",IF(H5=100,"✅ Completada",IF(F5="","",IF(F5<TODAY(),"🔴 Vencida",IF(G5<=5,"🟡 Por vencer","🟢 En tiempo"))))) | J5: =IF(H5="","",REPT("█",ROUND(H5/10,0))&" "&H5&"%")
A6: 3 | B6: P5 | G6: =IF(F6="","",F6-TODAY()) | I6: =IF(D6="","",IF(H6=100,"✅ Completada",IF(F6="","",IF(F6<TODAY(),"🔴 Vencida",IF(G6<=5,"🟡 Por vencer","🟢 En tiempo"))))) | J6: =IF(H6="","",REPT("█",ROUND(H6/10,0))&" "&H6&"%")
A7: 4 | B7: P5 | G7: =IF(F7="","",F7-TODAY()) | I7: =IF(D7="","",IF(H7=100,"✅ Completada",IF(F7="","",IF(F7<TODAY(),"🔴 Vencida",IF(G7<=5,"🟡 Por vencer","🟢 En tiempo"))))) | J7: =IF(H7="","",REPT("█",ROUND(H7/10,0))&" "&H7&"%")
A8: 5 | B8: P5 | G8: =IF(F8="","",F8-TODAY()) | I8: =IF(D8="","",IF(H8=100,"✅ Completada",IF(F8="","",IF(F8<TODAY(),"🔴 Vencida",IF(G8<=5,"🟡 Por vencer","🟢 En tiempo"))))) | J8: =IF(H8="","",REPT("█",ROUND(H8/10,0))&" "&H8&"%")
A9: 6 | B9: P5 | G9: =IF(F9="","",F9-TODAY()) | I9: =IF(D9="","",IF(H9=100,"✅ Completada",IF(F9="","",IF(F9<TODAY(),"🔴 Vencida",IF(G9<=5,"🟡 Por vencer","🟢 En tiempo"))))) | J9: =IF(H9="","",REPT("█",ROUND(H9/10,0))&" "&H9&"%")
A10: 7 | B10: P5 | G10: =IF(F10="","",F10-TODAY()) | I10: =IF(D10="","",IF(H10=100,"✅ Completada",IF(F10="","",IF(F10<TODAY(),"🔴 Vencida",IF(G10<=5,"🟡 Por vencer","🟢 En tiempo"))))) | J10: =IF(H10="","",REPT("█",ROUND(H10/10,0))&" "&H10&"%")
A11: 8 | B11: P5 | G11: =IF(F11="","",F11-TODAY()) | I11: =IF(D11="","",IF(H11=100,"✅ Completada",IF(F11="","",IF(F11<TODAY(),"🔴 Vencida",IF(G11<=5,"🟡 Por vencer","🟢 En tiempo"))))) | J11: =IF(H11="","",REPT("█",ROUND(H11/10,0))&" "&H11&"%")
A12: 9 | B12: P5 | G12: =IF(F12="","",F12-TODAY()) | I12: =IF(D12="","",IF(H12=100,"✅ Completada",IF(F12="","",IF(F12<TODAY(),"🔴 Vencida",IF(G12<=5,"🟡 Por vencer","🟢 En tiempo"))))) | J12: =IF(H12="","",REPT("█",ROUND(H12/10,0))&" "&H12&"%")
A13: 10 | B13: P5 | G13: =IF(F13="","",F13-TODAY()) | I13: =IF(D13="","",IF(H13=100,"✅ Completada",IF(F13="","",IF(F13<TODAY(),"🔴 Vencida",IF(G13<=5,"🟡 Por vencer","🟢 En tiempo"))))) | J13: =IF(H13="","",REPT("█",ROUND(H13/10,0))&" "&H13&"%")
A14: 11 | B14: P5 | G14: =IF(F14="","",F14-TODAY()) | I14: =IF(D14="","",IF(H14=100,"✅ Completada",IF(F14="","",IF(F14<TODAY(),"🔴 Vencida",IF(G14<=5,"🟡 Por vencer","🟢 En tiempo"))))) | J14: =IF(H14="","",REPT("█",ROUND(H14/10,0))&" "&H14&"%")
A15: 12 | B15: P5 | G15: =IF(F15="","",F15-TODAY()) | I15: =IF(D15="","",IF(H15=100,"✅ Completada",IF(F15="","",IF(F15<TODAY(),"🔴 Vencida",IF(G15<=5,"🟡 Por vencer","🟢 En tiempo"))))) | J15: =IF(H15="","",REPT("█",ROUND(H15/10,0))&" "&H15&"%")
... A18: 15 | B18: P5 | G18: =IF(F18="","",F18-TODAY()) | I18: =IF(D18="","",IF(H18=100,"✅ Completada",IF(F18="","",IF(F18<TODAY(),"🔴 Vencida",IF(G18<=5,"🟡 Por vencer","🟢 En tiempo"))))) | J18: =IF(H18="","",REPT("█",ROUND(H18/10,0))&" "&H18&"%")
A19: 📊 PROGRESO GENERAL DEL PROYECTO | H19: =IFERROR(AVERAGE(IF(H4:H18<>"",H4:H18)),0) -> 0 | I19: =COUNTIF(I4:I18,"✅ Completada")&" de "&COUNTA(D4:D18)&" tareas completadas" -> 0 de 0 tareas completadas

Sheet P6
A1: 📋 PLAN DE TRABAJO — P6: ARQUITECTURA EMPRESARIAL
A2: ⚠️ Campos AMARILLOS: ingresar datos | Campos GRISES: calculados automáticamente | % Avance: 0-100
A3: # | B3: ID | C3: FASE | D3: NOMBRE DE LA TAREA | E3: F. INICIO | F3: F. FIN COMPROMETIDA | G3: DÍAS REST. | H3: % AVANCE | I3: ESTADO | J3: PROGRESO
A4: 1 | B4: P6 | G4: =IF(F4="","",F4-TODAY()) | I4: =IF(D4="","",IF(H4=100,"✅ Completada",IF(F4="","",IF(F4<TODAY(),"🔴 Vencida",IF(G4<=5,"🟡 Por vencer","🟢 En tiempo"))))) | J4: =IF(H4="","",REPT("█",ROUND(H4/10,0))&" "&H4&"%")
A5: 2 | B5: P6 | G5: =IF(F5="","",F5-TODAY()) | I5: =IF(D5="","",IF(H5=100,"✅ Completada",IF(F5="","",IF(F5<TODAY(),"🔴 Vencida",IF(G5<=5,"🟡 Por vencer","🟢 En tiempo"))))) | J5: =IF(H5="","",REPT("█",ROUND(H5/10,0))&" "&H5&"%")
A6: 3 | B6: P6 | G6: =IF(F6="","",F6-TODAY()) | I6: =IF(D6="","",IF(H6=100,"✅ Completada",IF(F6="","",IF(F6<TODAY(),"🔴 Vencida",IF(G6<=5,"🟡 Por vencer","🟢 En tiempo"))))) | J6: =IF(H6="","",REPT("█",ROUND(H6/10,0))&" "&H6&"%")
A7: 4 | B7: P6 | G7: =IF(F7="","",F7-TODAY()) | I7: =IF(D7="","",IF(H7=100,"✅ Completada",IF(F7="","",IF(F7<TODAY(),"🔴 Vencida",IF(G7<=5,"🟡 Por vencer","🟢 En tiempo"))))) | J7: =IF(H7="","",REPT("█",ROUND(H7/10,0))&" "&H7&"%")
A8: 5 | B8: P6 | G8: =IF(F8="","",F8-TODAY()) | I8: =IF(D8="","",IF(H8=100,"✅ Completada",IF(F8="","",IF(F8<TODAY(),"🔴 Vencida",IF(G8<=5,"🟡 Por vencer","🟢 En tiempo"))))) | J8: =IF(H8="","",REPT("█",ROUND(H8/10,0))&" "&H8&"%")
A9: 6 | B9: P6 | G9: =IF(F9="","",F9-TODAY()) | I9: =IF(D9="","",IF(H9=100,"✅ Completada",IF(F9="","",IF(F9<TODAY(),"🔴 Vencida",IF(G9<=5,"🟡 Por vencer","🟢 En tiempo"))))) | J9: =IF(H9="","",REPT("█",ROUND(H9/10,0))&" "&H9&"%")
A10: 7 | B10: P6 | G10: =IF(F10="","",F10-TODAY()) | I10: =IF(D10="","",IF(H10=100,"✅ Completada",IF(F10="","",IF(F10<TODAY(),"🔴 Vencida",IF(G10<=5,"🟡 Por vencer","🟢 En tiempo"))))) | J10: =IF(H10="","",REPT("█",ROUND(H10/10,0))&" "&H10&"%")
A11: 8 | B11: P6 | G11: =IF(F11="","",F11-TODAY()) | I11: =IF(D11="","",IF(H11=100,"✅ Completada",IF(F11="","",IF(F11<TODAY(),"🔴 Vencida",IF(G11<=5,"🟡 Por vencer","🟢 En tiempo"))))) | J11: =IF(H11="","",REPT("█",ROUND(H11/10,0))&" "&H11&"%")
A12: 9 | B12: P6 | G12: =IF(F12="","",F12-TODAY()) | I12: =IF(D12="","",IF(H12=100,"✅ Completada",IF(F12="","",IF(F12<TODAY(),"🔴 Vencida",IF(G12<=5,"🟡 Por vencer","🟢 En tiempo"))))) | J12: =IF(H12="","",REPT("█",ROUND(H12/10,0))&" "&H12&"%")
A13: 10 | B13: P6 | G13: =IF(F13="","",F13-TODAY()) | I13: =IF(D13="","",IF(H13=100,"✅ Completada",IF(F13="","",IF(F13<TODAY(),"🔴 Vencida",IF(G13<=5,"🟡 Por vencer","🟢 En tiempo"))))) | J13: =IF(H13="","",REPT("█",ROUND(H13/10,0))&" "&H13&"%")
A14: 11 | B14: P6 | G14: =IF(F14="","",F14-TODAY()) | I14: =IF(D14="","",IF(H14=100,"✅ Completada",IF(F14="","",IF(F14<TODAY(),"🔴 Vencida",IF(G14<=5,"🟡 Por vencer","🟢 En tiempo"))))) | J14: =IF(H14="","",REPT("█",ROUND(H14/10,0))&" "&H14&"%")
A15: 12 | B15: P6 | G15: =IF(F15="","",F15-TODAY()) | I15: =IF(D15="","",IF(H15=100,"✅ Completada",IF(F15="","",IF(F15<TODAY(),"🔴 Vencida",IF(G15<=5,"🟡 Por vencer","🟢 En tiempo"))))) | J15: =IF(H15="","",REPT("█",ROUND(H15/10,0))&" "&H15&"%")
... A18: 15 | B18: P6 | G18: =IF(F18="","",F18-TODAY()) | I18: =IF(D18="","",IF(H18=100,"✅ Completada",IF(F18="","",IF(F18<TODAY(),"🔴 Vencida",IF(G18<=5,"🟡 Por vencer","🟢 En tiempo"))))) | J18: =IF(H18="","",REPT("█",ROUND(H18/10,0))&" "&H18&"%")
A19: 📊 PROGRESO GENERAL DEL PROYECTO | H19: =IFERROR(AVERAGE(IF(H4:H18<>"",H4:H18)),0) -> 0 | I19: =COUNTIF(I4:I18,"✅ Completada")&" de "&COUNTA(D4:D18)&" tareas completadas" -> 0 de 0 tareas completadas

Sheet P7
A1: 📋 PLAN DE TRABAJO — P7: LICENCIAS MICROSOFT
